# 오늘의 rxjs - Observable 2탄

지난 시간에 이어서 `Observable`에 대해 좀 더 살펴 보도록 하겠습니다.

이번엔 `오류`를 일으켜보고 덤으로 `완료`도 시켜 볼거에요!

비동기로 데이터 전달 시 부득이하게 오류를 일으켜야 하는 경우가 있습니다.

Promise 는 다음과 같이 했습니다. 기억 나시죠?

```ts
const prm = new Promise((resolve, reject) => {
  reject(new Error("오류에요 뿜뿜 ^^"));
});

prm.then((val) => console.log(val)).catch((err) => console.log(err.message));
// 오류에요 뿜뿜 ^^!
```

Observable 은 다음과 같은 방법으로 오류 상황을 받아낼 수 있습니다.

```ts
import { Observable } from "rxjs";

const obs = new Observable((subscriber) => {
  subscriber.error(new Error("오류에요 뿜뿜 ^^!"));
});

obs.subscribe(
  (val) => console.log(val),
  (err) => console.log(err.message)
);
// 오류에요 뿜뿜 ^^!
```

즉 Observable 에서 subscribe 할 때 첫번째 콜백 인자는 `onNext` 인 것이고, 두번째 인자는 `onError` 인 것입니다.

자, 그럼 마지막 3번째 인자로 완료(complete)를 시켜 보겠습니다.

완료는 Promise 에는 없는 특별한 기능입니다.

지속적으로 자료를 주던 옵저버가 `난 이제 너희에게 더이상 줄게 없으니 20000 작별하겠 3~!! 'ㅅ')/` ..과 같은 상태임을 구독자(Subscription)들에게 알려주는 기능 입니다.

완료는 subscribe 의 세번째 인자로써 아래와 같이 사용합니다.

```ts
import { Observable } from "rxjs";

const obs = new Observable((subscriber) => {
  subscriber.error(new Error("오류에요 뿜뿜 ^^!"));
  subscriber.complete();
});

obs.subscribe(
  (val) => console.log(val),
  (err) => console.log(err.message),
  () => console.log("완료!")
);
```

엇~! 근데 오류가 나니 완료로 가지 않는군요!

그럼 에러 부분을 잠시 주석 처리 하겠습니다.

```ts
import { Observable } from "rxjs";

const obs = new Observable((subscriber) => {
  // subscriber.error(new Error("오류에요 뿜뿜 ^^!"));
  subscriber.complete();
});

obs.subscribe(
  (val) => console.log(val),
  (err) => console.log(err.message),
  () => console.log("완료!") // 완료!
);
```

드디어 완료가 되네요. 그럼 자료를 몇번 전달 후 완료를 시켜 보도록 바꿔 보겠습니다.

```ts
import { Observable } from "rxjs";

const obs = new Observable((subscriber) => {
  subscriber.next(10);
  subscriber.next(12);
  subscriber.next(15);
  // subscriber.error(new Error("오류에요 뿜뿜 ^^!"));
  subscriber.complete();
});

obs.subscribe(
  (val) => console.log(val),
  (err) => console.log(err.message),
  () => console.log("완료!")
);
// 10, 12, 15, 완료!
```

이제 다시 오류를 살려 보겠습니다.

```ts
import { Observable } from "rxjs";

const obs = new Observable((subscriber) => {
  subscriber.next(10);
  subscriber.next(12);
  subscriber.next(15);
  subscriber.error(new Error("오류에요 뿜뿜 ^^!"));
  subscriber.complete();
});

obs.subscribe(
  (val) => console.log(val),
  (err) => console.log(err.message),
  () => console.log("완료!")
);
// 10, 12, 15, 오류에요 뿜뿜 ^^!
```

엇! 다시 `완료!` 가 뜨질 않습니다.

여기까지 쭉 보셨다면 한가지 이해 하셨을 것입니다.

Observable 로 subscribe 했을 때 `onError`가 발생되면 그대로 `비동기 자료 받기는 종료`가 된다는 사실을요!

다만 그게 **완료가 아님** 일 뿐이죠 :)

물론 `onComplete` 가 발생되어도 마찬가지겠죠?

지금까지 Observable 을 통한 오류와 완료 처리에 대해 살펴 봤습니다.

그럼 한가자 의문점이 드실거에요.

엇! Promise 는 .catch() 하고 chaining 으로 then() 으로 자료를 이어 받을 수 있는데 여긴 저걸로 끝인가효...? 하고 말이죠!

이 부분은 이 후 다뤄질 `operator` 에서 상세히 설명 드릴겁니다!

그럼 다음에도 봐요 ^-^)/

오늘도 good day~!

실습 장소: [바로가기](https://stackblitz.com/edit/ss-ts-rxjs-003)
